<?xml version="1.0" ?> <!-- =================================================================================== --> <!-- | This document was autogenerated by xacro from quicksilver.urdf.xacro | --> <!-- | EDITING THIS FILE BY HAND IS NOT RECOMMENDED | --> <!-- =================================================================================== --> <robot name="quicksilver"> <link name="base_footprint"/> <material name="white"> <color rgba="0 0 0 1"/> </material> <link name="base_link"> <visual> <geometry> <box size="0.75 0.75 0.03"/> </geometry> <origin rpy="0 0 0" xyz="0 0 0.04"/> <material name="white"/> </visual> <inertial> <origin rpy="0.0 0.0 0.0" xyz="0.0 0.0 0.04"/> <mass value="1"/> <inertia ixx="0.04695" ixy="0" ixz="0" iyy="0.04695" iyz="0" izz="0.09385"/> </inertial> <collision> <geometry> <box size="0.75 0.75 0.03"/> </geometry> </collision> </link> <joint name="base_joint" type="fixed"> <parent link="base_footprint"/> <child link="base_link"/> <origin xyz="0 0 0"/> </joint> <joint name="rplidar_joint" type="fixed"> <axis xyz="0 0 0"/> <origin rpy="0.0 0.0 0.0" xyz="0.0 0.0 0.09"/> <parent link="base_link"/> <child link="rplidar_link"/> </joint> <link name="rplidar_link"> <collision> <origin rpy="0.0 0.0 0.0" xyz="0.0 0.0 0.09"/> <geometry> <box size="0.1 0.1 0.1"/> </geometry> </collision> <visual> <origin rpy="1.5707 0 -1.5707" xyz="0 0 -0.03125"/> <geometry> <mesh filename="package://quicksilver_description/mesh/rplidar.stl" scale="0.001 0.001 0.001"/> <material> <color rgba="1 0.84 0 1"/> </material> </geometry> </visual> <inertial> <mass value="1e-5"/> <origin rpy="0 0 0" xyz="0 0 0"/> <inertia ixx="1e-6" ixy="0" ixz="0" iyy="1e-6" iyz="0" izz="1e-6"/> </inertial> </link> <gazebo reference="rplidar_link"> <material>Gazebo/Gold</material> <sensor name="head_rplidar_sensor" type="ray"> <pose>0 0 0 0 0 0</pose> <visualize>false</visualize> <update_rate>100</update_rate> <ray> <scan> <horizontal> <samples>1920</samples> <resolution>1</resolution> <min_angle>-3.14159265</min_angle> <max_angle>3.14159265</max_angle> </horizontal> </scan> <range> <min>0.2</min> <max>12.0</max> <resolution>1.0</resolution> </range> <noise> <type>gaussian</type> <mean>0.0</mean> <stddev>0.01</stddev> </noise> </ray> <plugin filename="libgazebo_ros_laser.so" name="gazebo_ros_head_rplidar_controller"> <topicName>/scan</topicName> <robotNamespace>/laser_scan/scan</robotNamespace> <frameName>rplidar_link</frameName> </plugin> </sensor> </gazebo> <link name="rim_wheel4_link"> <inertial> <origin xyz="0 0 -0.000343"/> <mass value="0.1"/> <inertia ixx="3.5882205135936479220061309613548e-5" ixy="0" ixz="0" iyy="3.5882205135936479220061309613548e-5" iyz="0" izz="4.2502518671672900528621921656748e-5"/> </inertial> <visual> <geometry> <mesh filename="package://quicksilver_description/mesh/rim.stl" scale="2 2 2"/> </geometry> <material name="rim_wheel4_material"> <color rgba="0.6 0 0 1"/> </material> </visual> <collision> <geometry> <mesh filename="package://quicksilver_description/mesh/rim.stl" scale="2 2 2"/> </geometry> </collision> </link> <joint name="rim_wheel4_joint" type="continuous"> <parent link="base_link"/> <child link="rim_wheel4_link"/> <axis xyz="0 0 1"/> <origin rpy="1.570796326794896 0 1.5708" xyz="-0.393 0 0.016"/> </joint> <link name="roller_e_rim_wheel4_link"> <inertial> <mass value="0.08"/> ! <!-- 0.0022769 0.0000000507552 0.0000000295332--> <inertia ixx="7.0801668935833809126443849093065e-6" ixy="0" ixz="0" iyy="7.0801668935833809126443849093065e-6" iyz="0" izz="2.4266818920462031709780842373402e-6"/> </inertial> <visual> <geometry> <mesh filename="package://quicksilver_description/mesh/roller.stl" scale="2 2 2"/> </geometry> <material name="roller_material"> <color rgba="0.1 0.1 0.1 1"/> </material> </visual> <collision> <geometry> <mesh filename="package://quicksilver_description/mesh/roller.stl" scale="2 2 2"/> </geometry> </collision> </link> <gazebo reference="roller_e_rim_wheel4_link"> <material>Gazebo/Black</material> </gazebo> <joint name="roller_e_rim_wheel4_joint" type="continuous"> <parent link="rim_wheel4_link"/> <child link="roller_e_rim_wheel4_link"/> <axis xyz="0 0 1"/> <origin rpy="-1.570796326794896 0 0" xyz="0.0271 0 0.011"/> </joint> <link name="roller_ne_rim_wheel4_link"> <inertial> <mass value="0.08"/> ! <!-- 0.0022769 0.0000000507552 0.0000000295332--> <inertia ixx="7.0801668935833809126443849093065e-6" ixy="0" ixz="0" iyy="7.0801668935833809126443849093065e-6" iyz="0" izz="2.4266818920462031709780842373402e-6"/> </inertial> <visual> <geometry> <mesh filename="package://quicksilver_description/mesh/roller.stl" scale="2 2 2"/> </geometry> <material name="roller_material"> <color rgba="0.1 0.1 0.1 1"/> </material> </visual> <collision> <geometry> <mesh filename="package://quicksilver_description/mesh/roller.stl" scale="2 2 2"/> </geometry> </collision> </link> <gazebo reference="roller_ne_rim_wheel4_link"> <material>Gazebo/Black</material> </gazebo> <joint name="roller_ne_rim_wheel4_joint" type="continuous"> <parent link="rim_wheel4_link"/> <child link="roller_ne_rim_wheel4_link"/> <axis xyz="0 0 1"/> <origin rpy="-1.570796326794896 0 0.7853981633974483" xyz="0.01916259378 0.01916259378 -0.011"/> </joint> <link name="roller_n_rim_wheel4_link"> <inertial> <mass value="0.08"/> ! <!-- 0.0022769 0.0000000507552 0.0000000295332--> <inertia ixx="7.0801668935833809126443849093065e-6" ixy="0" ixz="0" iyy="7.0801668935833809126443849093065e-6" iyz="0" izz="2.4266818920462031709780842373402e-6"/> </inertial> <visual> <geometry> <mesh filename="package://quicksilver_description/mesh/roller.stl" scale="2 2 2"/> </geometry> <material name="roller_material"> <color rgba="0.1 0.1 0.1 1"/> </material> </visual> <collision> <geometry> <mesh filename="package://quicksilver_description/mesh/roller.stl" scale="2 2 2"/> </geometry> </collision> </link> <gazebo reference="roller_n_rim_wheel4_link"> <material>Gazebo/Black</material> </gazebo> <joint name="roller_n_rim_wheel4_joint" type="continuous"> <parent link="rim_wheel4_link"/> <child link="roller_n_rim_wheel4_link"/> <axis xyz="0 0 1"/> <origin rpy="-1.570796326794896 0 1.570796326794896" xyz="0 0.0271 0.011"/> </joint> <link name="roller_nw_rim_wheel4_link"> <inertial> <mass value="0.08"/> ! <!-- 0.0022769 0.0000000507552 0.0000000295332--> <inertia ixx="7.0801668935833809126443849093065e-6" ixy="0" ixz="0" iyy="7.0801668935833809126443849093065e-6" iyz="0" izz="2.4266818920462031709780842373402e-6"/> </inertial> <visual> <geometry> <mesh filename="package://quicksilver_description/mesh/roller.stl" scale="2 2 2"/> </geometry> <material name="roller_material"> <color rgba="0.1 0.1 0.1 1"/> </material> </visual> <collision> <geometry> <mesh filename="package://quicksilver_description/mesh/roller.stl" scale="2 2 2"/> </geometry> </collision> </link> <gazebo reference="roller_nw_rim_wheel4_link"> <material>Gazebo/Black</material> </gazebo> <joint name="roller_nw_rim_wheel4_joint" type="continuous"> <parent link="rim_wheel4_link"/> <child link="roller_nw_rim_wheel4_link"/> <axis xyz="0 0 1"/> <origin rpy="-1.570796326794896 0 2.356194490192345" xyz="-0.01916259378 0.01916259378 -0.011"/> </joint> <link name="roller_w_rim_wheel4_link"> <inertial> <mass value="0.08"/> ! <!-- 0.0022769 0.0000000507552 0.0000000295332--> <inertia ixx="7.0801668935833809126443849093065e-6" ixy="0" ixz="0" iyy="7.0801668935833809126443849093065e-6" iyz="0" izz="2.4266818920462031709780842373402e-6"/> </inertial> <visual> <geometry> <mesh filename="package://quicksilver_description/mesh/roller.stl" scale="2 2 2"/> </geometry> <material name="roller_material"> <color rgba="0.1 0.1 0.1 1"/> </material> </visual> <collision> <geometry> <mesh filename="package://quicksilver_description/mesh/roller.stl" scale="2 2 2"/> </geometry> </collision> </link> <gazebo reference="roller_w_rim_wheel4_link"> <material>Gazebo/Black</material> </gazebo> <joint name="roller_w_rim_wheel4_joint" type="continuous"> <parent link="rim_wheel4_link"/> <child link="roller_w_rim_wheel4_link"/> <axis xyz="0 0 1"/> <origin rpy="-1.570796326794896 0 3.141592653589793" xyz="-0.0271 0 0.011"/> </joint> <link name="roller_sw_rim_wheel4_link"> <inertial> <mass value="0.08"/> ! <!-- 0.0022769 0.0000000507552 0.0000000295332--> <inertia ixx="7.0801668935833809126443849093065e-6" ixy="0" ixz="0" iyy="7.0801668935833809126443849093065e-6" iyz="0" izz="2.4266818920462031709780842373402e-6"/> </inertial> <visual> <geometry> <mesh filename="package://quicksilver_description/mesh/roller.stl" scale="2 2 2"/> </geometry> <material name="roller_material"> <color rgba="0.1 0.1 0.1 1"/> </material> </visual> <collision> <geometry> <mesh filename="package://quicksilver_description/mesh/roller.stl" scale="2 2 2"/> </geometry> </collision> </link> <gazebo reference="roller_sw_rim_wheel4_link"> <material>Gazebo/Black</material> </gazebo> <joint name="roller_sw_rim_wheel4_joint" type="continuous"> <parent link="rim_wheel4_link"/> <child link="roller_sw_rim_wheel4_link"/> <axis xyz="0 0 1"/> <origin rpy="-1.570796326794896 0 -2.356194490192345" xyz="-0.01916259378 -0.01916259378 -0.011"/> </joint> <link name="roller_s_rim_wheel4_link"> <inertial> <mass value="0.08"/> ! <!-- 0.0022769 0.0000000507552 0.0000000295332--> <inertia ixx="7.0801668935833809126443849093065e-6" ixy="0" ixz="0" iyy="7.0801668935833809126443849093065e-6" iyz="0" izz="2.4266818920462031709780842373402e-6"/> </inertial> <visual> <geometry> <mesh filename="package://quicksilver_description/mesh/roller.stl" scale="2 2 2"/> </geometry> <material name="roller_material"> <color rgba="0.1 0.1 0.1 1"/> </material> </visual> <collision> <geometry> <mesh filename="package://quicksilver_description/mesh/roller.stl" scale="2 2 2"/> </geometry> </collision> </link> <gazebo reference="roller_s_rim_wheel4_link"> <material>Gazebo/Black</material> </gazebo> <joint name="roller_s_rim_wheel4_joint" type="continuous"> <parent link="rim_wheel4_link"/> <child link="roller_s_rim_wheel4_link"/> <axis xyz="0 0 1"/> <origin rpy="-1.570796326794896 0 -1.570796326794896" xyz="0 -0.0271 0.011"/> </joint> <link name="roller_se_rim_wheel4_link"> <inertial> <mass value="0.08"/> ! <!-- 0.0022769 0.0000000507552 0.0000000295332--> <inertia ixx="7.0801668935833809126443849093065e-6" ixy="0" ixz="0" iyy="7.0801668935833809126443849093065e-6" iyz="0" izz="2.4266818920462031709780842373402e-6"/> </inertial> <visual> <geometry> <mesh filename="package://quicksilver_description/mesh/roller.stl" scale="2 2 2"/> </geometry> <material name="roller_material"> <color rgba="0.1 0.1 0.1 1"/> </material> </visual> <collision> <geometry> <mesh filename="package://quicksilver_description/mesh/roller.stl" scale="2 2 2"/> </geometry> </collision> </link> <gazebo reference="roller_se_rim_wheel4_link"> <material>Gazebo/Black</material> </gazebo> <joint name="roller_se_rim_wheel4_joint" type="continuous"> <parent link="rim_wheel4_link"/> <child link="roller_se_rim_wheel4_link"/> <axis xyz="0 0 1"/> <origin rpy="-1.570796326794896 0 -0.7853981633974483" xyz="0.01916259378 -0.01916259378 -0.011"/> </joint> <!-- <transmission>标签唯一指定了一个传动的标签，name可以自己定义，也可以与joint名相同。 <type>标签指定了传动的类型，选择transmission_interface/SimpleTransmission即可。 <joint>标签（可定义一个或多个）指定这个传动所依赖的关节，拥有如下标签<hardwareInterface>。 <hardwareInterface>（在joint下，可定义一个或多个）指定支持的硬件接口空间。用于结合控制器使用硬件接口来向硬件接口发送和接受指令，请注意： ①当在RobotHW中加载此transmission时，此标签的值应为hardware_interface / XXX。 ②在Gazebo中加载此transmission时，此标记的值应为XXX。 <actuator>标签（定义一个或多个）指定了与joint传动连接的执行器，名字可以随意定义，拥有如下标签<mechanicalReduction>、<hardwareInterface>及<motorTorqueConstant>。 <mechanicalReduction>（可选）定义了电机／关节减速比。 <hardwareInterface>（可选，只有Indigo及以前版本的在这里指定，目前版本已经移到joint标签下）定义了支持的硬件接口。 <motorTorqueConstant>（可选）定义了电机的转矩参数。 --> <transmission name="rim_wheel4_transmission"> <type>transmission_interface/SimpleTransmission</type> <joint name="rim_wheel4_joint"> <hardwareInterface>hardware_interface/VelocityJointInterface</hardwareInterface> </joint> <actuator name="rim_wheel4_motor"> <hardwareInterface>hardware_interface/VelocityJointInterface</hardwareInterface> <mechanicalReduction>1</mechanicalReduction> </actuator> </transmission> <link name="rim_wheel3_link"> <inertial> <origin xyz="0 0 -0.000343"/> <mass value="0.1"/> <inertia ixx="3.5882205135936479220061309613548e-5" ixy="0" ixz="0" iyy="3.5882205135936479220061309613548e-5" iyz="0" izz="4.2502518671672900528621921656748e-5"/> </inertial> <visual> <geometry> <mesh filename="package://quicksilver_description/mesh/rim.stl" scale="2 2 2"/> </geometry> <material name="rim_wheel3_material"> <color rgba="0 0.6 0 1"/> </material> </visual> <collision> <geometry> <mesh filename="package://quicksilver_description/mesh/rim.stl" scale="2 2 2"/> </geometry> </collision> </link> <joint name="rim_wheel3_joint" type="continuous"> <parent link="base_link"/> <child link="rim_wheel3_link"/> <axis xyz="0 0 1"/> <origin rpy="1.570796326794896 0 3.141592653589793" xyz="0 -0.393 0.016"/> </joint> <link name="roller_e_rim_wheel3_link"> <inertial> <mass value="0.08"/> ! <!-- 0.0022769 0.0000000507552 0.0000000295332--> <inertia ixx="7.0801668935833809126443849093065e-6" ixy="0" ixz="0" iyy="7.0801668935833809126443849093065e-6" iyz="0" izz="2.4266818920462031709780842373402e-6"/> </inertial> <visual> <geometry> <mesh filename="package://quicksilver_description/mesh/roller.stl" scale="2 2 2"/> </geometry> <material name="roller_material"> <color rgba="0.1 0.1 0.1 1"/> </material> </visual> <collision> <geometry> <mesh filename="package://quicksilver_description/mesh/roller.stl" scale="2 2 2"/> </geometry> </collision> </link> <gazebo reference="roller_e_rim_wheel3_link"> <material>Gazebo/Black</material> </gazebo> <joint name="roller_e_rim_wheel3_joint" type="continuous"> <parent link="rim_wheel3_link"/> <child link="roller_e_rim_wheel3_link"/> <axis xyz="0 0 1"/> <origin rpy="-1.570796326794896 0 0" xyz="0.0271 0 0.011"/> </joint> <link name="roller_ne_rim_wheel3_link"> <inertial> <mass value="0.08"/> ! <!-- 0.0022769 0.0000000507552 0.0000000295332--> <inertia ixx="7.0801668935833809126443849093065e-6" ixy="0" ixz="0" iyy="7.0801668935833809126443849093065e-6" iyz="0" izz="2.4266818920462031709780842373402e-6"/> </inertial> <visual> <geometry> <mesh filename="package://quicksilver_description/mesh/roller.stl" scale="2 2 2"/> </geometry> <material name="roller_material"> <color rgba="0.1 0.1 0.1 1"/> </material> </visual> <collision> <geometry> <mesh filename="package://quicksilver_description/mesh/roller.stl" scale="2 2 2"/> </geometry> </collision> </link> <gazebo reference="roller_ne_rim_wheel3_link"> <material>Gazebo/Black</material> </gazebo> <joint name="roller_ne_rim_wheel3_joint" type="continuous"> <parent link="rim_wheel3_link"/> <child link="roller_ne_rim_wheel3_link"/> <axis xyz="0 0 1"/> <origin rpy="-1.570796326794896 0 0.7853981633974483" xyz="0.01916259378 0.01916259378 -0.011"/> </joint> <link name="roller_n_rim_wheel3_link"> <inertial> <mass value="0.08"/> ! <!-- 0.0022769 0.0000000507552 0.0000000295332--> <inertia ixx="7.0801668935833809126443849093065e-6" ixy="0" ixz="0" iyy="7.0801668935833809126443849093065e-6" iyz="0" izz="2.4266818920462031709780842373402e-6"/> </inertial> <visual> <geometry> <mesh filename="package://quicksilver_description/mesh/roller.stl" scale="2 2 2"/> </geometry> <material name="roller_material"> <color rgba="0.1 0.1 0.1 1"/> </material> </visual> <collision> <geometry> <mesh filename="package://quicksilver_description/mesh/roller.stl" scale="2 2 2"/> </geometry> </collision> </link> <gazebo reference="roller_n_rim_wheel3_link"> <material>Gazebo/Black</material> </gazebo> <joint name="roller_n_rim_wheel3_joint" type="continuous"> <parent link="rim_wheel3_link"/> <child link="roller_n_rim_wheel3_link"/> <axis xyz="0 0 1"/> <origin rpy="-1.570796326794896 0 1.570796326794896" xyz="0 0.0271 0.011"/> </joint> <link name="roller_nw_rim_wheel3_link"> <inertial> <mass value="0.08"/> ! <!-- 0.0022769 0.0000000507552 0.0000000295332--> <inertia ixx="7.0801668935833809126443849093065e-6" ixy="0" ixz="0" iyy="7.0801668935833809126443849093065e-6" iyz="0" izz="2.4266818920462031709780842373402e-6"/> </inertial> <visual> <geometry> <mesh filename="package://quicksilver_description/mesh/roller.stl" scale="2 2 2"/> </geometry> <material name="roller_material"> <color rgba="0.1 0.1 0.1 1"/> </material> </visual> <collision> <geometry> <mesh filename="package://quicksilver_description/mesh/roller.stl" scale="2 2 2"/> </geometry> </collision> </link> <gazebo reference="roller_nw_rim_wheel3_link"> <material>Gazebo/Black</material> </gazebo> <joint name="roller_nw_rim_wheel3_joint" type="continuous"> <parent link="rim_wheel3_link"/> <child link="roller_nw_rim_wheel3_link"/> <axis xyz="0 0 1"/> <origin rpy="-1.570796326794896 0 2.356194490192345" xyz="-0.01916259378 0.01916259378 -0.011"/> </joint> <link name="roller_w_rim_wheel3_link"> <inertial> <mass value="0.08"/> ! <!-- 0.0022769 0.0000000507552 0.0000000295332--> <inertia ixx="7.0801668935833809126443849093065e-6" ixy="0" ixz="0" iyy="7.0801668935833809126443849093065e-6" iyz="0" izz="2.4266818920462031709780842373402e-6"/> </inertial> <visual> <geometry> <mesh filename="package://quicksilver_description/mesh/roller.stl" scale="2 2 2"/> </geometry> <material name="roller_material"> <color rgba="0.1 0.1 0.1 1"/> </material> </visual> <collision> <geometry> <mesh filename="package://quicksilver_description/mesh/roller.stl" scale="2 2 2"/> </geometry> </collision> </link> <gazebo reference="roller_w_rim_wheel3_link"> <material>Gazebo/Black</material> </gazebo> <joint name="roller_w_rim_wheel3_joint" type="continuous"> <parent link="rim_wheel3_link"/> <child link="roller_w_rim_wheel3_link"/> <axis xyz="0 0 1"/> <origin rpy="-1.570796326794896 0 3.141592653589793" xyz="-0.0271 0 0.011"/> </joint> <link name="roller_sw_rim_wheel3_link"> <inertial> <mass value="0.08"/> ! <!-- 0.0022769 0.0000000507552 0.0000000295332--> <inertia ixx="7.0801668935833809126443849093065e-6" ixy="0" ixz="0" iyy="7.0801668935833809126443849093065e-6" iyz="0" izz="2.4266818920462031709780842373402e-6"/> </inertial> <visual> <geometry> <mesh filename="package://quicksilver_description/mesh/roller.stl" scale="2 2 2"/> </geometry> <material name="roller_material"> <color rgba="0.1 0.1 0.1 1"/> </material> </visual> <collision> <geometry> <mesh filename="package://quicksilver_description/mesh/roller.stl" scale="2 2 2"/> </geometry> </collision> </link> <gazebo reference="roller_sw_rim_wheel3_link"> <material>Gazebo/Black</material> </gazebo> <joint name="roller_sw_rim_wheel3_joint" type="continuous"> <parent link="rim_wheel3_link"/> <child link="roller_sw_rim_wheel3_link"/> <axis xyz="0 0 1"/> <origin rpy="-1.570796326794896 0 -2.356194490192345" xyz="-0.01916259378 -0.01916259378 -0.011"/> </joint> <link name="roller_s_rim_wheel3_link"> <inertial> <mass value="0.08"/> ! <!-- 0.0022769 0.0000000507552 0.0000000295332--> <inertia ixx="7.0801668935833809126443849093065e-6" ixy="0" ixz="0" iyy="7.0801668935833809126443849093065e-6" iyz="0" izz="2.4266818920462031709780842373402e-6"/> </inertial> <visual> <geometry> <mesh filename="package://quicksilver_description/mesh/roller.stl" scale="2 2 2"/> </geometry> <material name="roller_material"> <color rgba="0.1 0.1 0.1 1"/> </material> </visual> <collision> <geometry> <mesh filename="package://quicksilver_description/mesh/roller.stl" scale="2 2 2"/> </geometry> </collision> </link> <gazebo reference="roller_s_rim_wheel3_link"> <material>Gazebo/Black</material> </gazebo> <joint name="roller_s_rim_wheel3_joint" type="continuous"> <parent link="rim_wheel3_link"/> <child link="roller_s_rim_wheel3_link"/> <axis xyz="0 0 1"/> <origin rpy="-1.570796326794896 0 -1.570796326794896" xyz="0 -0.0271 0.011"/> </joint> <link name="roller_se_rim_wheel3_link"> <inertial> <mass value="0.08"/> ! <!-- 0.0022769 0.0000000507552 0.0000000295332--> <inertia ixx="7.0801668935833809126443849093065e-6" ixy="0" ixz="0" iyy="7.0801668935833809126443849093065e-6" iyz="0" izz="2.4266818920462031709780842373402e-6"/> </inertial> <visual> <geometry> <mesh filename="package://quicksilver_description/mesh/roller.stl" scale="2 2 2"/> </geometry> <material name="roller_material"> <color rgba="0.1 0.1 0.1 1"/> </material> </visual> <collision> <geometry> <mesh filename="package://quicksilver_description/mesh/roller.stl" scale="2 2 2"/> </geometry> </collision> </link> <gazebo reference="roller_se_rim_wheel3_link"> <material>Gazebo/Black</material> </gazebo> <joint name="roller_se_rim_wheel3_joint" type="continuous"> <parent link="rim_wheel3_link"/> <child link="roller_se_rim_wheel3_link"/> <axis xyz="0 0 1"/> <origin rpy="-1.570796326794896 0 -0.7853981633974483" xyz="0.01916259378 -0.01916259378 -0.011"/> </joint> <!-- <transmission>标签唯一指定了一个传动的标签，name可以自己定义，也可以与joint名相同。 <type>标签指定了传动的类型，选择transmission_interface/SimpleTransmission即可。 <joint>标签（可定义一个或多个）指定这个传动所依赖的关节，拥有如下标签<hardwareInterface>。 <hardwareInterface>（在joint下，可定义一个或多个）指定支持的硬件接口空间。用于结合控制器使用硬件接口来向硬件接口发送和接受指令，请注意： ①当在RobotHW中加载此transmission时，此标签的值应为hardware_interface / XXX。 ②在Gazebo中加载此transmission时，此标记的值应为XXX。 <actuator>标签（定义一个或多个）指定了与joint传动连接的执行器，名字可以随意定义，拥有如下标签<mechanicalReduction>、<hardwareInterface>及<motorTorqueConstant>。 <mechanicalReduction>（可选）定义了电机／关节减速比。 <hardwareInterface>（可选，只有Indigo及以前版本的在这里指定，目前版本已经移到joint标签下）定义了支持的硬件接口。 <motorTorqueConstant>（可选）定义了电机的转矩参数。 --> <transmission name="rim_wheel3_transmission"> <type>transmission_interface/SimpleTransmission</type> <joint name="rim_wheel3_joint"> <hardwareInterface>hardware_interface/VelocityJointInterface</hardwareInterface> </joint> <actuator name="rim_wheel3_motor"> <hardwareInterface>hardware_interface/VelocityJointInterface</hardwareInterface> <mechanicalReduction>1</mechanicalReduction> </actuator> </transmission> <link name="rim_wheel2_link"> <inertial> <origin xyz="0 0 -0.000343"/> <mass value="0.1"/> <inertia ixx="3.5882205135936479220061309613548e-5" ixy="0" ixz="0" iyy="3.5882205135936479220061309613548e-5" iyz="0" izz="4.2502518671672900528621921656748e-5"/> </inertial> <visual> <geometry> <mesh filename="package://quicksilver_description/mesh/rim.stl" scale="2 2 2"/> </geometry> <material name="rim_wheel2_material"> <color rgba="0.6 0 0 1"/> </material> </visual> <collision> <geometry> <mesh filename="package://quicksilver_description/mesh/rim.stl" scale="2 2 2"/> </geometry> </collision> </link> <joint name="rim_wheel2_joint" type="continuous"> <parent link="base_link"/> <child link="rim_wheel2_link"/> <axis xyz="0 0 1"/> <origin rpy="1.570796326794896 0 -1.5708" xyz="0.393 0 0.016"/> </joint> <link name="roller_e_rim_wheel2_link"> <inertial> <mass value="0.08"/> ! <!-- 0.0022769 0.0000000507552 0.0000000295332--> <inertia ixx="7.0801668935833809126443849093065e-6" ixy="0" ixz="0" iyy="7.0801668935833809126443849093065e-6" iyz="0" izz="2.4266818920462031709780842373402e-6"/> </inertial> <visual> <geometry> <mesh filename="package://quicksilver_description/mesh/roller.stl" scale="2 2 2"/> </geometry> <material name="roller_material"> <color rgba="0.1 0.1 0.1 1"/> </material> </visual> <collision> <geometry> <mesh filename="package://quicksilver_description/mesh/roller.stl" scale="2 2 2"/> </geometry> </collision> </link> <gazebo reference="roller_e_rim_wheel2_link"> <material>Gazebo/Black</material> </gazebo> <joint name="roller_e_rim_wheel2_joint" type="continuous"> <parent link="rim_wheel2_link"/> <child link="roller_e_rim_wheel2_link"/> <axis xyz="0 0 1"/> <origin rpy="-1.570796326794896 0 0" xyz="0.0271 0 0.011"/> </joint> <link name="roller_ne_rim_wheel2_link"> <inertial> <mass value="0.08"/> ! <!-- 0.0022769 0.0000000507552 0.0000000295332--> <inertia ixx="7.0801668935833809126443849093065e-6" ixy="0" ixz="0" iyy="7.0801668935833809126443849093065e-6" iyz="0" izz="2.4266818920462031709780842373402e-6"/> </inertial> <visual> <geometry> <mesh filename="package://quicksilver_description/mesh/roller.stl" scale="2 2 2"/> </geometry> <material name="roller_material"> <color rgba="0.1 0.1 0.1 1"/> </material> </visual> <collision> <geometry> <mesh filename="package://quicksilver_description/mesh/roller.stl" scale="2 2 2"/> </geometry> </collision> </link> <gazebo reference="roller_ne_rim_wheel2_link"> <material>Gazebo/Black</material> </gazebo> <joint name="roller_ne_rim_wheel2_joint" type="continuous"> <parent link="rim_wheel2_link"/> <child link="roller_ne_rim_wheel2_link"/> <axis xyz="0 0 1"/> <origin rpy="-1.570796326794896 0 0.7853981633974483" xyz="0.01916259378 0.01916259378 -0.011"/> </joint> <link name="roller_n_rim_wheel2_link"> <inertial> <mass value="0.08"/> ! <!-- 0.0022769 0.0000000507552 0.0000000295332--> <inertia ixx="7.0801668935833809126443849093065e-6" ixy="0" ixz="0" iyy="7.0801668935833809126443849093065e-6" iyz="0" izz="2.4266818920462031709780842373402e-6"/> </inertial> <visual> <geometry> <mesh filename="package://quicksilver_description/mesh/roller.stl" scale="2 2 2"/> </geometry> <material name="roller_material"> <color rgba="0.1 0.1 0.1 1"/> </material> </visual> <collision> <geometry> <mesh filename="package://quicksilver_description/mesh/roller.stl" scale="2 2 2"/> </geometry> </collision> </link> <gazebo reference="roller_n_rim_wheel2_link"> <material>Gazebo/Black</material> </gazebo> <joint name="roller_n_rim_wheel2_joint" type="continuous"> <parent link="rim_wheel2_link"/> <child link="roller_n_rim_wheel2_link"/> <axis xyz="0 0 1"/> <origin rpy="-1.570796326794896 0 1.570796326794896" xyz="0 0.0271 0.011"/> </joint> <link name="roller_nw_rim_wheel2_link"> <inertial> <mass value="0.08"/> ! <!-- 0.0022769 0.0000000507552 0.0000000295332--> <inertia ixx="7.0801668935833809126443849093065e-6" ixy="0" ixz="0" iyy="7.0801668935833809126443849093065e-6" iyz="0" izz="2.4266818920462031709780842373402e-6"/> </inertial> <visual> <geometry> <mesh filename="package://quicksilver_description/mesh/roller.stl" scale="2 2 2"/> </geometry> <material name="roller_material"> <color rgba="0.1 0.1 0.1 1"/> </material> </visual> <collision> <geometry> <mesh filename="package://quicksilver_description/mesh/roller.stl" scale="2 2 2"/> </geometry> </collision> </link> <gazebo reference="roller_nw_rim_wheel2_link"> <material>Gazebo/Black</material> </gazebo> <joint name="roller_nw_rim_wheel2_joint" type="continuous"> <parent link="rim_wheel2_link"/> <child link="roller_nw_rim_wheel2_link"/> <axis xyz="0 0 1"/> <origin rpy="-1.570796326794896 0 2.356194490192345" xyz="-0.01916259378 0.01916259378 -0.011"/> </joint> <link name="roller_w_rim_wheel2_link"> <inertial> <mass value="0.08"/> ! <!-- 0.0022769 0.0000000507552 0.0000000295332--> <inertia ixx="7.0801668935833809126443849093065e-6" ixy="0" ixz="0" iyy="7.0801668935833809126443849093065e-6" iyz="0" izz="2.4266818920462031709780842373402e-6"/> </inertial> <visual> <geometry> <mesh filename="package://quicksilver_description/mesh/roller.stl" scale="2 2 2"/> </geometry> <material name="roller_material"> <color rgba="0.1 0.1 0.1 1"/> </material> </visual> <collision> <geometry> <mesh filename="package://quicksilver_description/mesh/roller.stl" scale="2 2 2"/> </geometry> </collision> </link> <gazebo reference="roller_w_rim_wheel2_link"> <material>Gazebo/Black</material> </gazebo> <joint name="roller_w_rim_wheel2_joint" type="continuous"> <parent link="rim_wheel2_link"/> <child link="roller_w_rim_wheel2_link"/> <axis xyz="0 0 1"/> <origin rpy="-1.570796326794896 0 3.141592653589793" xyz="-0.0271 0 0.011"/> </joint> <link name="roller_sw_rim_wheel2_link"> <inertial> <mass value="0.08"/> ! <!-- 0.0022769 0.0000000507552 0.0000000295332--> <inertia ixx="7.0801668935833809126443849093065e-6" ixy="0" ixz="0" iyy="7.0801668935833809126443849093065e-6" iyz="0" izz="2.4266818920462031709780842373402e-6"/> </inertial> <visual> <geometry> <mesh filename="package://quicksilver_description/mesh/roller.stl" scale="2 2 2"/> </geometry> <material name="roller_material"> <color rgba="0.1 0.1 0.1 1"/> </material> </visual> <collision> <geometry> <mesh filename="package://quicksilver_description/mesh/roller.stl" scale="2 2 2"/> </geometry> </collision> </link> <gazebo reference="roller_sw_rim_wheel2_link"> <material>Gazebo/Black</material> </gazebo> <joint name="roller_sw_rim_wheel2_joint" type="continuous"> <parent link="rim_wheel2_link"/> <child link="roller_sw_rim_wheel2_link"/> <axis xyz="0 0 1"/> <origin rpy="-1.570796326794896 0 -2.356194490192345" xyz="-0.01916259378 -0.01916259378 -0.011"/> </joint> <link name="roller_s_rim_wheel2_link"> <inertial> <mass value="0.08"/> ! <!-- 0.0022769 0.0000000507552 0.0000000295332--> <inertia ixx="7.0801668935833809126443849093065e-6" ixy="0" ixz="0" iyy="7.0801668935833809126443849093065e-6" iyz="0" izz="2.4266818920462031709780842373402e-6"/> </inertial> <visual> <geometry> <mesh filename="package://quicksilver_description/mesh/roller.stl" scale="2 2 2"/> </geometry> <material name="roller_material"> <color rgba="0.1 0.1 0.1 1"/> </material> </visual> <collision> <geometry> <mesh filename="package://quicksilver_description/mesh/roller.stl" scale="2 2 2"/> </geometry> </collision> </link> <gazebo reference="roller_s_rim_wheel2_link"> <material>Gazebo/Black</material> </gazebo> <joint name="roller_s_rim_wheel2_joint" type="continuous"> <parent link="rim_wheel2_link"/> <child link="roller_s_rim_wheel2_link"/> <axis xyz="0 0 1"/> <origin rpy="-1.570796326794896 0 -1.570796326794896" xyz="0 -0.0271 0.011"/> </joint> <link name="roller_se_rim_wheel2_link"> <inertial> <mass value="0.08"/> ! <!-- 0.0022769 0.0000000507552 0.0000000295332--> <inertia ixx="7.0801668935833809126443849093065e-6" ixy="0" ixz="0" iyy="7.0801668935833809126443849093065e-6" iyz="0" izz="2.4266818920462031709780842373402e-6"/> </inertial> <visual> <geometry> <mesh filename="package://quicksilver_description/mesh/roller.stl" scale="2 2 2"/> </geometry> <material name="roller_material"> <color rgba="0.1 0.1 0.1 1"/> </material> </visual> <collision> <geometry> <mesh filename="package://quicksilver_description/mesh/roller.stl" scale="2 2 2"/> </geometry> </collision> </link> <gazebo reference="roller_se_rim_wheel2_link"> <material>Gazebo/Black</material> </gazebo> <joint name="roller_se_rim_wheel2_joint" type="continuous"> <parent link="rim_wheel2_link"/> <child link="roller_se_rim_wheel2_link"/> <axis xyz="0 0 1"/> <origin rpy="-1.570796326794896 0 -0.7853981633974483" xyz="0.01916259378 -0.01916259378 -0.011"/> </joint> <!-- <transmission>标签唯一指定了一个传动的标签，name可以自己定义，也可以与joint名相同。 <type>标签指定了传动的类型，选择transmission_interface/SimpleTransmission即可。 <joint>标签（可定义一个或多个）指定这个传动所依赖的关节，拥有如下标签<hardwareInterface>。 <hardwareInterface>（在joint下，可定义一个或多个）指定支持的硬件接口空间。用于结合控制器使用硬件接口来向硬件接口发送和接受指令，请注意： ①当在RobotHW中加载此transmission时，此标签的值应为hardware_interface / XXX。 ②在Gazebo中加载此transmission时，此标记的值应为XXX。 <actuator>标签（定义一个或多个）指定了与joint传动连接的执行器，名字可以随意定义，拥有如下标签<mechanicalReduction>、<hardwareInterface>及<motorTorqueConstant>。 <mechanicalReduction>（可选）定义了电机／关节减速比。 <hardwareInterface>（可选，只有Indigo及以前版本的在这里指定，目前版本已经移到joint标签下）定义了支持的硬件接口。 <motorTorqueConstant>（可选）定义了电机的转矩参数。 --> <transmission name="rim_wheel2_transmission"> <type>transmission_interface/SimpleTransmission</type> <joint name="rim_wheel2_joint"> <hardwareInterface>hardware_interface/VelocityJointInterface</hardwareInterface> </joint> <actuator name="rim_wheel2_motor"> <hardwareInterface>hardware_interface/VelocityJointInterface</hardwareInterface> <mechanicalReduction>1</mechanicalReduction> </actuator> </transmission> <link name="rim_wheel1_link"> <inertial> <origin xyz="0 0 -0.000343"/> <mass value="0.1"/> <inertia ixx="3.5882205135936479220061309613548e-5" ixy="0" ixz="0" iyy="3.5882205135936479220061309613548e-5" iyz="0" izz="4.2502518671672900528621921656748e-5"/> </inertial> <visual> <geometry> <mesh filename="package://quicksilver_description/mesh/rim.stl" scale="2 2 2"/> </geometry> <material name="rim_wheel1_material"> <color rgba="0 0.6 0.0 1"/> </material> </visual> <collision> <geometry> <mesh filename="package://quicksilver_description/mesh/rim.stl" scale="2 2 2"/> </geometry> </collision> </link> <joint name="rim_wheel1_joint" type="continuous"> <parent link="base_link"/> <child link="rim_wheel1_link"/> <axis xyz="0 0 1"/> <origin rpy="1.570796326794896 0 0" xyz="0 0.393 0.016"/> </joint> <link name="roller_e_rim_wheel1_link"> <inertial> <mass value="0.08"/> ! <!-- 0.0022769 0.0000000507552 0.0000000295332--> <inertia ixx="7.0801668935833809126443849093065e-6" ixy="0" ixz="0" iyy="7.0801668935833809126443849093065e-6" iyz="0" izz="2.4266818920462031709780842373402e-6"/> </inertial> <visual> <geometry> <mesh filename="package://quicksilver_description/mesh/roller.stl" scale="2 2 2"/> </geometry> <material name="roller_material"> <color rgba="0.1 0.1 0.1 1"/> </material> </visual> <collision> <geometry> <mesh filename="package://quicksilver_description/mesh/roller.stl" scale="2 2 2"/> </geometry> </collision> </link> <gazebo reference="roller_e_rim_wheel1_link"> <material>Gazebo/Black</material> </gazebo> <joint name="roller_e_rim_wheel1_joint" type="continuous"> <parent link="rim_wheel1_link"/> <child link="roller_e_rim_wheel1_link"/> <axis xyz="0 0 1"/> <origin rpy="-1.570796326794896 0 0" xyz="0.0271 0 0.011"/> </joint> <link name="roller_ne_rim_wheel1_link"> <inertial> <mass value="0.08"/> ! <!-- 0.0022769 0.0000000507552 0.0000000295332--> <inertia ixx="7.0801668935833809126443849093065e-6" ixy="0" ixz="0" iyy="7.0801668935833809126443849093065e-6" iyz="0" izz="2.4266818920462031709780842373402e-6"/> </inertial> <visual> <geometry> <mesh filename="package://quicksilver_description/mesh/roller.stl" scale="2 2 2"/> </geometry> <material name="roller_material"> <color rgba="0.1 0.1 0.1 1"/> </material> </visual> <collision> <geometry> <mesh filename="package://quicksilver_description/mesh/roller.stl" scale="2 2 2"/> </geometry> </collision> </link> <gazebo reference="roller_ne_rim_wheel1_link"> <material>Gazebo/Black</material> </gazebo> <joint name="roller_ne_rim_wheel1_joint" type="continuous"> <parent link="rim_wheel1_link"/> <child link="roller_ne_rim_wheel1_link"/> <axis xyz="0 0 1"/> <origin rpy="-1.570796326794896 0 0.7853981633974483" xyz="0.01916259378 0.01916259378 -0.011"/> </joint> <link name="roller_n_rim_wheel1_link"> <inertial> <mass value="0.08"/> ! <!-- 0.0022769 0.0000000507552 0.0000000295332--> <inertia ixx="7.0801668935833809126443849093065e-6" ixy="0" ixz="0" iyy="7.0801668935833809126443849093065e-6" iyz="0" izz="2.4266818920462031709780842373402e-6"/> </inertial> <visual> <geometry> <mesh filename="package://quicksilver_description/mesh/roller.stl" scale="2 2 2"/> </geometry> <material name="roller_material"> <color rgba="0.1 0.1 0.1 1"/> </material> </visual> <collision> <geometry> <mesh filename="package://quicksilver_description/mesh/roller.stl" scale="2 2 2"/> </geometry> </collision> </link> <gazebo reference="roller_n_rim_wheel1_link"> <material>Gazebo/Black</material> </gazebo> <joint name="roller_n_rim_wheel1_joint" type="continuous"> <parent link="rim_wheel1_link"/> <child link="roller_n_rim_wheel1_link"/> <axis xyz="0 0 1"/> <origin rpy="-1.570796326794896 0 1.570796326794896" xyz="0 0.0271 0.011"/> </joint> <link name="roller_nw_rim_wheel1_link"> <inertial> <mass value="0.08"/> ! <!-- 0.0022769 0.0000000507552 0.0000000295332--> <inertia ixx="7.0801668935833809126443849093065e-6" ixy="0" ixz="0" iyy="7.0801668935833809126443849093065e-6" iyz="0" izz="2.4266818920462031709780842373402e-6"/> </inertial> <visual> <geometry> <mesh filename="package://quicksilver_description/mesh/roller.stl" scale="2 2 2"/> </geometry> <material name="roller_material"> <color rgba="0.1 0.1 0.1 1"/> </material> </visual> <collision> <geometry> <mesh filename="package://quicksilver_description/mesh/roller.stl" scale="2 2 2"/> </geometry> </collision> </link> <gazebo reference="roller_nw_rim_wheel1_link"> <material>Gazebo/Black</material> </gazebo> <joint name="roller_nw_rim_wheel1_joint" type="continuous"> <parent link="rim_wheel1_link"/> <child link="roller_nw_rim_wheel1_link"/> <axis xyz="0 0 1"/> <origin rpy="-1.570796326794896 0 2.356194490192345" xyz="-0.01916259378 0.01916259378 -0.011"/> </joint> <link name="roller_w_rim_wheel1_link"> <inertial> <mass value="0.08"/> ! <!-- 0.0022769 0.0000000507552 0.0000000295332--> <inertia ixx="7.0801668935833809126443849093065e-6" ixy="0" ixz="0" iyy="7.0801668935833809126443849093065e-6" iyz="0" izz="2.4266818920462031709780842373402e-6"/> </inertial> <visual> <geometry> <mesh filename="package://quicksilver_description/mesh/roller.stl" scale="2 2 2"/> </geometry> <material name="roller_material"> <color rgba="0.1 0.1 0.1 1"/> </material> </visual> <collision> <geometry> <mesh filename="package://quicksilver_description/mesh/roller.stl" scale="2 2 2"/> </geometry> </collision> </link> <gazebo reference="roller_w_rim_wheel1_link"> <material>Gazebo/Black</material> </gazebo> <joint name="roller_w_rim_wheel1_joint" type="continuous"> <parent link="rim_wheel1_link"/> <child link="roller_w_rim_wheel1_link"/> <axis xyz="0 0 1"/> <origin rpy="-1.570796326794896 0 3.141592653589793" xyz="-0.0271 0 0.011"/> </joint> <link name="roller_sw_rim_wheel1_link"> <inertial> <mass value="0.08"/> ! <!-- 0.0022769 0.0000000507552 0.0000000295332--> <inertia ixx="7.0801668935833809126443849093065e-6" ixy="0" ixz="0" iyy="7.0801668935833809126443849093065e-6" iyz="0" izz="2.4266818920462031709780842373402e-6"/> </inertial> <visual> <geometry> <mesh filename="package://quicksilver_description/mesh/roller.stl" scale="2 2 2"/> </geometry> <material name="roller_material"> <color rgba="0.1 0.1 0.1 1"/> </material> </visual> <collision> <geometry> <mesh filename="package://quicksilver_description/mesh/roller.stl" scale="2 2 2"/> </geometry> </collision> </link> <gazebo reference="roller_sw_rim_wheel1_link"> <material>Gazebo/Black</material> </gazebo> <joint name="roller_sw_rim_wheel1_joint" type="continuous"> <parent link="rim_wheel1_link"/> <child link="roller_sw_rim_wheel1_link"/> <axis xyz="0 0 1"/> <origin rpy="-1.570796326794896 0 -2.356194490192345" xyz="-0.01916259378 -0.01916259378 -0.011"/> </joint> <link name="roller_s_rim_wheel1_link"> <inertial> <mass value="0.08"/> ! <!-- 0.0022769 0.0000000507552 0.0000000295332--> <inertia ixx="7.0801668935833809126443849093065e-6" ixy="0" ixz="0" iyy="7.0801668935833809126443849093065e-6" iyz="0" izz="2.4266818920462031709780842373402e-6"/> </inertial> <visual> <geometry> <mesh filename="package://quicksilver_description/mesh/roller.stl" scale="2 2 2"/> </geometry> <material name="roller_material"> <color rgba="0.1 0.1 0.1 1"/> </material> </visual> <collision> <geometry> <mesh filename="package://quicksilver_description/mesh/roller.stl" scale="2 2 2"/> </geometry> </collision> </link> <gazebo reference="roller_s_rim_wheel1_link"> <material>Gazebo/Black</material> </gazebo> <joint name="roller_s_rim_wheel1_joint" type="continuous"> <parent link="rim_wheel1_link"/> <child link="roller_s_rim_wheel1_link"/> <axis xyz="0 0 1"/> <origin rpy="-1.570796326794896 0 -1.570796326794896" xyz="0 -0.0271 0.011"/> </joint> <link name="roller_se_rim_wheel1_link"> <inertial> <mass value="0.08"/> ! <!-- 0.0022769 0.0000000507552 0.0000000295332--> <inertia ixx="7.0801668935833809126443849093065e-6" ixy="0" ixz="0" iyy="7.0801668935833809126443849093065e-6" iyz="0" izz="2.4266818920462031709780842373402e-6"/> </inertial> <visual> <geometry> <mesh filename="package://quicksilver_description/mesh/roller.stl" scale="2 2 2"/> </geometry> <material name="roller_material"> <color rgba="0.1 0.1 0.1 1"/> </material> </visual> <collision> <geometry> <mesh filename="package://quicksilver_description/mesh/roller.stl" scale="2 2 2"/> </geometry> </collision> </link> <gazebo reference="roller_se_rim_wheel1_link"> <material>Gazebo/Black</material> </gazebo> <joint name="roller_se_rim_wheel1_joint" type="continuous"> <parent link="rim_wheel1_link"/> <child link="roller_se_rim_wheel1_link"/> <axis xyz="0 0 1"/> <origin rpy="-1.570796326794896 0 -0.7853981633974483" xyz="0.01916259378 -0.01916259378 -0.011"/> </joint> <!-- <transmission>标签唯一指定了一个传动的标签，name可以自己定义，也可以与joint名相同。 <type>标签指定了传动的类型，选择transmission_interface/SimpleTransmission即可。 <joint>标签（可定义一个或多个）指定这个传动所依赖的关节，拥有如下标签<hardwareInterface>。 <hardwareInterface>（在joint下，可定义一个或多个）指定支持的硬件接口空间。用于结合控制器使用硬件接口来向硬件接口发送和接受指令，请注意： ①当在RobotHW中加载此transmission时，此标签的值应为hardware_interface / XXX。 ②在Gazebo中加载此transmission时，此标记的值应为XXX。 <actuator>标签（定义一个或多个）指定了与joint传动连接的执行器，名字可以随意定义，拥有如下标签<mechanicalReduction>、<hardwareInterface>及<motorTorqueConstant>。 <mechanicalReduction>（可选）定义了电机／关节减速比。 <hardwareInterface>（可选，只有Indigo及以前版本的在这里指定，目前版本已经移到joint标签下）定义了支持的硬件接口。 <motorTorqueConstant>（可选）定义了电机的转矩参数。 --> <transmission name="rim_wheel1_transmission"> <type>transmission_interface/SimpleTransmission</type> <joint name="rim_wheel1_joint"> <hardwareInterface>hardware_interface/VelocityJointInterface</hardwareInterface> </joint> <actuator name="rim_wheel1_motor"> <hardwareInterface>hardware_interface/VelocityJointInterface</hardwareInterface> <mechanicalReduction>1</mechanicalReduction> </actuator> </transmission> <gazebo reference="base_link"> <material>Gazebo/Black</material> <mu1>0.2</mu1> <mu2>0.2</mu2> <kp>500000.0</kp> <kd>10.0</kd> <minDepth>0.001</minDepth> <maxVel>0.5</maxVel> <fdir1>1 0 0</fdir1> </gazebo> <gazebo reference="rim_wheel3_link"> <material>Gazebo/Green</material> <mu1>0.2</mu1> <mu2>0.2</mu2> <kp>500000.0</kp> <kd>10.0</kd> <minDepth>0.001</minDepth> <maxVel>0.5</maxVel> <fdir1>1 0 0</fdir1> </gazebo> <gazebo reference="rim_wheel4_link"> <material>Gazebo/Red</material> <mu1>0.2</mu1> <mu2>0.2</mu2> <kp>500000.0</kp> <kd>10.0</kd> <minDepth>0.001</minDepth> <maxVel>0.5</maxVel> <fdir1>1 0 0</fdir1> </gazebo> <gazebo reference="rim_wheel1_link"> <material>Gazebo/Green</material> <mu1>0.2</mu1> <mu2>0.2</mu2> <kp>500000.0</kp> <kd>10.0</kd> <minDepth>0.001</minDepth> <maxVel>0.5</maxVel> <fdir1>1 0 0</fdir1> </gazebo> <gazebo reference="rim_wheel2_link"> <material>Gazebo/Red</material> <mu1>0.2</mu1> <mu2>0.2</mu2> <kp>500000.0</kp> <kd>10.0</kd> <minDepth>0.001</minDepth> <maxVel>0.5</maxVel> <fdir1>1 0 0</fdir1> </gazebo> <!--roscontrol built paramater config:config文件夹目录下car_joint.yaml --> <!-- <robotNamespace>用来定义插件其对象的ROS命名空间，默认是URDF或者SDF对应的机器人名称。 <contolPeriod>用来定义控制器的更新周期，单位为秒，默认使用Gazebo的周期。 <robotParam>用来定义ROS参数服务器上的机器人描述(URDF)路径，默认是"/robot_description"。 <robotSimType>用来定义机器人仿真接口所使用的插件库名称，默认是"DefaultRobotHWSim"。 <legacyModeNS>用来兼容之前ROS版本的配置。 --> <gazebo> <plugin filename="libgazebo_ros_control.so" name="gazebo_ros_control"> <robotNamespace>/quicksilver</robotNamespace> </plugin> </gazebo> </robot>
